Workbook

Sheet Cálculos
A1: 41509
A2: MVRC
AO3: Ing. J. Oscar T. Morales García | AP3: Director técnico
AO4: Ing. J. Oscar T. Morales García | AP4: Jefe de área SF&G | AQ4: Mess Servicios Metrológicos S. de R.L. de C.V.
AQ5: Instalaciones del cliente
AO6: Ing. Pablo Lopez Perez
B10: TENSION ELECTRICA CONTINUA
B11: INTERVALO | C11: 0 | D11: A | E11: 600
B12: RESOLUCION | C12: 0.1 | H12: para 5
B13: UNIDAD | C13: mV | D13: Error max: | E13: {=MAX(Q19:Q23)} -> 0.1 | F13: {=C13} -> mV | H13: muestras | I13: Especificación
D14: Incertidumbre max: | E14: {=MAX(O19:O23)} -> 0.057763846 | F14: {=C13} -> mV | I14: MK-019
I15: FLUKE
B16: Valor Nominal | H16: t= 1.4 | I16: 5502 | O16: Uexpandida
B17: del Patrón | C17: Muestra 1 | D17: Muestra 2 | E17: Muestra 3 | F17: Muestra 4 | G17: Muestra 5 | H17: uA | I17: Tol.de Patrón | J17: uB de Patrón | K17: uB resol. | L17: uC | M17: Grados | O17: para 95.45%
B18: {=C13} -> mV | C18: {=$B18} -> mV | D18: {=$B18} -> mV | E18: {=$B18} -> mV | F18: {=$B18} -> mV | G18: {=$B18} -> mV | H18: {=$B18} -> mV | I18: {=$B18} -> mV | J18: {=$B18} -> mV | ... L18: {=$B18} -> mV | M18: de libertad | N18: Factor k | O18: {=$B18} -> mV | Q18: error | R18: error +U | S18: error -U | T18: error_abs
B19: {=E11*0.1} -> 60 | C19: 60 | D19: 60 | E19: 60 | F19: 60 | G19: 60 | H19: {=STDEV(C19:G19)*1.4} -> 0 | I19: {=0.00316/2} -> 0.00158 | J19: {=I19/SQRT(3)} -> 0.00091221343 | K19: {=(C$12)/SQRT(12)} -> 0.028867513 | L19: {=SQRT(H19^2+J19^2+(K19)^2)} -> 0.028881923 | M19: {=IF(ISERROR((L19^4)/(H19^4/4))=TRUE,"∞",((L19^4)/(H19^4/4)))} -> ∞ | N19: {=IF(ISERROR(TINV(0.05,M19))=TRUE,2,TINV(0.05,M19))} -> 2 | O19: {=L19*N19} -> 0.057763846 | Q19: {=AVERAGE(C19:G19)-B19} -> 0 | R19: {=Q19+O19} -> 0.057763846 | S19: {=Q19-O19} -> -0.057763846 | T19: {=ABS(Q19)} -> 0
B20: {=E11*0.25} -> 150 | C20: 150 | D20: 150 | E20: 150 | F20: 150 | G20: 150 | H20: {=STDEV(C20:G20)*1.4} -> 0 | I20: {=0.00316/2} -> 0.00158 | J20: {=I20/SQRT(3)} -> 0.00091221343 | K20: {=(C$12)/SQRT(12)} -> 0.028867513 | L20: {=SQRT(H20^2+J20^2+(K20)^2)} -> 0.028881923 | M20: {=IF(ISERROR((L20^4)/(H20^4/4))=TRUE,"∞",((L20^4)/(H20^4/4)))} -> ∞ | N20: {=IF(ISERROR(TINV(0.05,M20))=TRUE,2,TINV(0.05,M20))} -> 2 | O20: {=L20*N20} -> 0.057763846 | Q20: {=AVERAGE(C20:G20)-B20} -> 0 | R20: {=Q20+O20} -> 0.057763846 | S20: {=Q20-O20} -> -0.057763846 | T20: {=ABS(Q20)} -> 0
B21: {=E11*0.5} -> 300 | C21: 300 | D21: 300 | E21: 300 | F21: 300 | G21: 300 | H21: {=STDEV(C21:G21)*1.4} -> 0 | I21: {=0.00316/2} -> 0.00158 | J21: {=I21/SQRT(3)} -> 0.00091221343 | K21: {=(C$12)/SQRT(12)} -> 0.028867513 | L21: {=SQRT(H21^2+J21^2+(K21)^2)} -> 0.028881923 | M21: {=IF(ISERROR((L21^4)/(H21^4/4))=TRUE,"∞",((L21^4)/(H21^4/4)))} -> ∞ | N21: {=IF(ISERROR(TINV(0.05,M21))=TRUE,2,TINV(0.05,M21))} -> 2 | O21: {=L21*N21} -> 0.057763846 | Q21: {=AVERAGE(C21:G21)-B21} -> 0 | R21: {=Q21+O21} -> 0.057763846 | S21: {=Q21-O21} -> -0.057763846 | T21: {=ABS(Q21)} -> 0
B22: {=E11*0.75} -> 450 | C22: 450.1 | D22: 450.1 | E22: 450.1 | F22: 450.1 | G22: 450.1 | H22: {=STDEV(C22:G22)*1.4} -> 0 | I22: {=0.00316/2} -> 0.00158 | J22: {=I22/SQRT(3)} -> 0.00091221343 | K22: {=(C$12)/SQRT(12)} -> 0.028867513 | L22: {=SQRT(H22^2+J22^2+(K22)^2)} -> 0.028881923 | M22: {=IF(ISERROR((L22^4)/(H22^4/4))=TRUE,"∞",((L22^4)/(H22^4/4)))} -> ∞ | N22: {=IF(ISERROR(TINV(0.05,M22))=TRUE,2,TINV(0.05,M22))} -> 2 | O22: {=L22*N22} -> 0.057763846 | Q22: {=AVERAGE(C22:G22)-B22} -> 0.1 | R22: {=Q22+O22} -> 0.15776385 | S22: {=Q22-O22} -> 0.042236154 | T22: {=ABS(Q22)} -> 0.1
B23: {=E11*0.9} -> 540 | C23: 540.1 | D23: 540.1 | E23: 540.1 | F23: 540.1 | G23: 540.1 | H23: {=STDEV(C23:G23)*1.4} -> 0 | I23: {=0.00316/2} -> 0.00158 | J23: {=I23/SQRT(3)} -> 0.00091221343 | K23: {=(C$12)/SQRT(12)} -> 0.028867513 | L23: {=SQRT(H23^2+J23^2+(K23)^2)} -> 0.028881923 | M23: {=IF(ISERROR((L23^4)/(H23^4/4))=TRUE,"∞",((L23^4)/(H23^4/4)))} -> ∞ | N23: {=IF(ISERROR(TINV(0.05,M23))=TRUE,2,TINV(0.05,M23))} -> 2 | O23: {=L23*N23} -> 0.057763846 | Q23: {=AVERAGE(C23:G23)-B23} -> 0.1 | R23: {=Q23+O23} -> 0.15776385 | S23: {=Q23-O23} -> 0.042236154 | T23: {=ABS(Q23)} -> 0.1
B25: TENSION ELECTRICA CONTINUA
B26: INTERVALO | C26: 0 | D26: A | E26: 6
B27: RESOLUCION | C27: 0.001 | H27: para 5
B28: UNIDAD | C28: V | D28: Error max: | E28: {=MAX(Q34:Q38)} -> 0 | F28: {=C28} -> V | H28: muestras | I28: Especificación
D29: Incertidumbre max: | E29: {=MAX(O34:O38)} -> 0.0039501055 | F29: {=C28} -> V | I29: MK-019
I30: FLUKE
B31: Valor Nominal | H31: t= 1.4 | I31: 5502 | O31: Uexpandida
B32: del Patrón | C32: Muestra 1 | D32: Muestra 2 | E32: Muestra 3 | F32: Muestra 4 | G32: Muestra 5 | H32: uA | I32: Tol.de Patrón | J32: uB de Patrón | K32: uB resol. | L32: uC | M32: Grados | O32: para 95.45%
B33: {=C28} -> V | C33: {=$B33} -> V | D33: {=$B33} -> V | E33: {=$B33} -> V | F33: {=$B33} -> V | G33: {=$B33} -> V | H33: {=$B33} -> V | I33: {=$B33} -> V | J33: {=$B33} -> V | ... L33: {=$B33} -> V | M33: de libertad | N33: Factor k | O33: {=$B33} -> V | Q33: error | R33: error +U | S33: error -U | T33: error_abs
B34: {=E26*0.1} -> 0.6 | C34: 0.6 | D34: 0.6 | E34: 0.6 | F34: 0.6 | G34: 0.6 | H34: {=STDEV(C34:G34)*1.4} -> 0 | I34: {=0.0059/2} -> 0.00295 | J34: {=I34/SQRT(3)} -> 0.0017031833 | K34: {=C$27} -> 0.001 | L34: {=SQRT(H34^2+J34^2+(K34)^2)} -> 0.0019750527 | M34: {=IF(ISERROR((L34^4)/(H34^4/4))=TRUE,"∞",((L34^4)/(H34^4/4)))} -> ∞ | N34: {=IF(ISERROR(TINV(0.05,M34))=TRUE,2,TINV(0.05,M34))} -> 2 | O34: {=L34*N34} -> 0.0039501055 | Q34: {=AVERAGE(C34:G34)-B34} -> 0 | R34: {=Q34+O34} -> 0.0039501055 | S34: {=Q34-O34} -> -0.0039501055 | T34: {=ABS(Q34)} -> 0
B35: {=E26*0.25} -> 1.5 | C35: 1.499 | D35: 1.499 | E35: 1.499 | F35: 1.499 | G35: 1.499 | H35: {=STDEV(C35:G35)*1.4} -> 0 | I35: {=0.0059/2} -> 0.00295 | J35: {=I35/SQRT(3)} -> 0.0017031833 | K35: {=C$27} -> 0.001 | L35: {=SQRT(H35^2+J35^2+(K35)^2)} -> 0.0019750527 | M35: {=IF(ISERROR((L35^4)/(H35^4/4))=TRUE,"∞",((L35^4)/(H35^4/4)))} -> ∞ | N35: {=IF(ISERROR(TINV(0.05,M35))=TRUE,2,TINV(0.05,M35))} -> 2 | O35: {=L35*N35} -> 0.0039501055 | Q35: {=AVERAGE(C35:G35)-B35} -> -0.001 | R35: {=Q35+O35} -> 0.0029501055 | S35: {=Q35-O35} -> -0.0049501055 | T35: {=ABS(Q35)} -> 0.001
B36: {=E26*0.5} -> 3 | C36: 2.998 | D36: 2.998 | E36: 2.998 | F36: 2.998 | G36: 2.998 | H36: {=STDEV(C36:G36)*1.4} -> 0 | I36: {=0.0059/2} -> 0.00295 | J36: {=I36/SQRT(3)} -> 0.0017031833 | K36: {=C$27} -> 0.001 | L36: {=SQRT(H36^2+J36^2+(K36)^2)} -> 0.0019750527 | M36: {=IF(ISERROR((L36^4)/(H36^4/4))=TRUE,"∞",((L36^4)/(H36^4/4)))} -> ∞ | N36: {=IF(ISERROR(TINV(0.05,M36))=TRUE,2,TINV(0.05,M36))} -> 2 | O36: {=L36*N36} -> 0.0039501055 | Q36: {=AVERAGE(C36:G36)-B36} -> -0.002 | R36: {=Q36+O36} -> 0.0019501055 | S36: {=Q36-O36} -> -0.0059501055 | T36: {=ABS(Q36)} -> 0.002
B37: {=E26*0.75} -> 4.5 | C37: 4.497 | D37: 4.497 | E37: 4.497 | F37: 4.497 | G37: 4.497 | H37: {=STDEV(C37:G37)*1.4} -> 0 | I37: {=0.0059/2} -> 0.00295 | J37: {=I37/SQRT(3)} -> 0.0017031833 | K37: {=C$27} -> 0.001 | L37: {=SQRT(H37^2+J37^2+(K37)^2)} -> 0.0019750527 | M37: {=IF(ISERROR((L37^4)/(H37^4/4))=TRUE,"∞",((L37^4)/(H37^4/4)))} -> ∞ | N37: {=IF(ISERROR(TINV(0.05,M37))=TRUE,2,TINV(0.05,M37))} -> 2 | O37: {=L37*N37} -> 0.0039501055 | Q37: {=AVERAGE(C37:G37)-B37} -> -0.003 | R37: {=Q37+O37} -> 0.00095010548 | S37: {=Q37-O37} -> -0.0069501055 | T37: {=ABS(Q37)} -> 0.003
B38: {=E26*0.9} -> 5.4 | C38: 5.397 | D38: 5.397 | E38: 5.397 | F38: 5.397 | G38: 5.397 | H38: {=STDEV(C38:G38)*1.4} -> 0 | I38: {=0.0059/2} -> 0.00295 | J38: {=I38/SQRT(3)} -> 0.0017031833 | K38: {=C$27} -> 0.001 | L38: {=SQRT(H38^2+J38^2+(K38)^2)} -> 0.0019750527 | M38: {=IF(ISERROR((L38^4)/(H38^4/4))=TRUE,"∞",((L38^4)/(H38^4/4)))} -> ∞ | N38: {=IF(ISERROR(TINV(0.05,M38))=TRUE,2,TINV(0.05,M38))} -> 2 | O38: {=L38*N38} -> 0.0039501055 | Q38: {=AVERAGE(C38:G38)-B38} -> -0.003 | R38: {=Q38+O38} -> 0.00095010548 | S38: {=Q38-O38} -> -0.0069501055 | T38: {=ABS(Q38)} -> 0.003
B40: TENSION ELECTRICA CONTINUA
B41: INTERVALO | C41: 0 | D41: A | E41: 60
B42: RESOLUCION | C42: 0.01 | H42: para 5
B43: UNIDAD | C43: V | D43: Error max: | E43: {=MAX(Q49:Q53)} -> 0 | F43: {=C43} -> V | H43: muestras | I43: Especificación
D44: Incertidumbre max: | E44: {=MAX(O49:O53)} -> 0.0064293597 | F44: {=C43} -> V | I44: MK-019
I45: FLUKE
...

Sheet Certificado
A1: E-MK-0153/26 | B1: MULTIMETRO DIGITAL | C1: FLUKE | D1: 116 | E1: 35260913WS | F1: EVO-559 | G1: RECICLADORA INDUSTRIAL DE ACUMULADORES, S.A. DE C.V. | H1: CARRETERA A GARCIA KM. 1.2 S/N, C.P. 66350 | I1: SANTA CATARINA | J1: NUEVO LEÓN | K1: 46037 | L1: 46037 | M1: {=K1+365} -> 46402 | N1: 46035
B3: CERTIFICADO DE CALIBRACIÓN (CALIBRATION CERTIFICATE) | G3: No. de certificado: (Certificate number) | I3: {=A1} -> E-MK-0153/26
C5: Datos del cliente: ( Customer ) | I5: Fecha de calibración: (Calibration date) | J5: {=K1} -> 46037
C6: Nombre: (Name) | D6: {=G1} -> RECICLADORA INDUSTRIAL DE ACUMULADORES, S.A. DE C.V. | I6: Fecha de emisión: (Date issued) | J6: {=L1} -> 46037
C7: Domicilio: (Address) | D7: {=H1} -> CARRETERA A GARCIA KM. 1.2 S/N, C.P. 66350 | I7: Vigencia solicitada: (Due date required) | J7: {=M1} -> 46402
D8: {=CONCATENATE(I1,", ",J1)} -> SANTA CATARINA, NUEVO LEÓN | I8: Fecha de recepcion: (Reception date) | J8: {=N1} -> 46035
I9: Página (Page): | J9: 1 de 6
C11: Descripción del Instrumento: (Instrument description)
H12: Lugar de la calibración: | I12: METKAL
C13: Instrumento : | D13: {=B1} -> MULTIMETRO DIGITAL
C14: (Instrument) | G14: Temperatura : | I14: 19.8
C15: Marca: | D15: {=C1} -> FLUKE | G15: (Temperature)
C16: (Manufacturer) | G16: Humedad Relativa : | I16: 0.471
C17: Modelo: | D17: {=D1} -> 116 | G17: (Relative Humidity)
C18: (Model)
C19: No. serie: | D19: {=E1} -> 35260913WS
C20: (Serial number)
C21: ID Interno: | D21: {=F1} -> EVO-559
C22: (Customer ID)
C23: Intervalo : | D23: VER RESULTADOS
C24: (Range)
C25: Resolución: | D25: VER RESULTADOS
C26: (Resolution)
C29: El laboratorio de calibraciones cuenta con un sistema de Gestión de Procesos basado en: | I29: ISO/IEC 17025:2017
C30: Requisitos generales para la competencia de los laboratorios de ensayo y de calibración.
C32: Procedimiento utilizado | E32: 7.2E1, 7.2E4, 7.2E5 | G32: Método: | H32: Comparación directa
C33: (Procedure used) | G33: (Method)
C35: Patrones empleados en la calibración (Measurement standard description)
C38: Descripción del patrón | E38: Certificado / Informe | G38: Vigencia | I38: ID interno
D39: (Description) | E39: (Certificate number) | G39: (Validity) | I39: (Internal ID)
D41: CALIBRADOR MULTIFUNCIONAL | E41: MF-CE-12019-11 | G41: 46218 | I41: MK-016
D46: Calibró: | E46: Miguel A. Bernal Cordero | G46: Firma
D47: (Calibrated by:) | E47: Ingeniero de Servicio | G47: (Signature)
D49: Aprobó: | E49: Sergio Garza Rangel | G49: Firma
D50: (Approved by:) | E50: Director Administrativo | G50: (Signature)

Sheet Resultados I
H9: No. de certificado: (Calibration number) | J9: {=Certificado!I3} -> E-MK-0153/26
C10: CERTIFICADO DE CALIBRACIÓN (CALIBRATION CERTIFICATE) | H10: Fecha de calibración: (Calibration date) | J10: {=Certificado!J5} -> 46037
H11: Fecha de emision: (Issued date) | J11: {=Certificado!J6} -> 46037
H12: Página: (Page) | J12: {=CONCATENATE(J13," de ",J274)} -> 2 de 6
J13: 2 | K13: 7
C14: Magnitud: | D14: {='Cálculos'!B10} -> TENSION ELECTRICA CONTINUA
G15: Unidad
C16: Intervalo de medida: | D16: {='Cálculos'!C11} -> 0 | E16: a | F16: {='Cálculos'!E11} -> 600 | G16: {='Cálculos'!C13} -> mV
C18: Division minima: | D18: {='Cálculos'!C12} -> 0.1
C20: Valor nominal | D20: Valor medido del instrumento | E20: Error de medida | F20: Incertidumbre
C21: del Patrón
C22: {='Cálculos'!B19} -> 60 | D22: {=AVERAGE('Cálculos'!C19:G19)} -> 60 | E22: {=D22-C22} -> 0 | F22: {='Cálculos'!O19} -> 0.057763846
C23: {='Cálculos'!B20} -> 150 | D23: {=AVERAGE('Cálculos'!C20:G20)} -> 150 | E23: {=D23-C23} -> 0 | F23: {='Cálculos'!O20} -> 0.057763846
C24: {='Cálculos'!B21} -> 300 | D24: {=AVERAGE('Cálculos'!C21:G21)} -> 300 | E24: {=D24-C24} -> 0 | F24: {='Cálculos'!O21} -> 0.057763846
C25: {='Cálculos'!B22} -> 450 | D25: {=AVERAGE('Cálculos'!C22:G22)} -> 450.1 | E25: {=D25-C25} -> 0.1 | F25: {='Cálculos'!O22} -> 0.057763846
C26: {='Cálculos'!B23} -> 540 | D26: {=AVERAGE('Cálculos'!C23:G23)} -> 540.1 | E26: {=D26-C26} -> 0.1 | F26: {='Cálculos'!O23} -> 0.057763846
C29: Magnitud: | D29: {='Cálculos'!B25} -> TENSION ELECTRICA CONTINUA
G30: Unidad
C31: Intervalo de medida: | D31: {='Cálculos'!C26} -> 0 | E31: a | F31: {='Cálculos'!E26} -> 6 | G31: {='Cálculos'!C28} -> V
C33: Division minima: | D33: {='Cálculos'!C27} -> 0.001
C35: Valor nominal | D35: Valor medido del instrumento | E35: Error de medida | F35: Incertidumbre
C36: del Patrón
C37: {='Cálculos'!B34} -> 0.6 | D37: {=AVERAGE('Cálculos'!C34:G34)} -> 0.6 | E37: {=D37-C37} -> 0 | F37: {='Cálculos'!O34} -> 0.0039501055
C38: {='Cálculos'!B35} -> 1.5 | D38: {=AVERAGE('Cálculos'!C35:G35)} -> 1.499 | E38: {=D38-C38} -> -0.001 | F38: {='Cálculos'!O35} -> 0.0039501055
C39: {='Cálculos'!B36} -> 3 | D39: {=AVERAGE('Cálculos'!C36:G36)} -> 2.998 | E39: {=D39-C39} -> -0.002 | F39: {='Cálculos'!O36} -> 0.0039501055
C40: {='Cálculos'!B37} -> 4.5 | D40: {=AVERAGE('Cálculos'!C37:G37)} -> 4.497 | E40: {=D40-C40} -> -0.003 | F40: {='Cálculos'!O37} -> 0.0039501055
C41: {='Cálculos'!B38} -> 5.4 | D41: {=AVERAGE('Cálculos'!C38:G38)} -> 5.397 | E41: {=D41-C41} -> -0.003 | F41: {='Cálculos'!O38} -> 0.0039501055
C44: Magnitud: | D44: {='Cálculos'!B40} -> TENSION ELECTRICA CONTINUA
G45: Unidad
C46: Intervalo de medida: | D46: {='Cálculos'!C41} -> 0 | E46: a | F46: {='Cálculos'!E41} -> 60 | G46: {='Cálculos'!C43} -> V
C48: Division minima: | D48: {='Cálculos'!C42} -> 0.01
C50: Valor nominal | D50: Valor medido del instrumento | E50: Error de medida | F50: Incertidumbre
C51: del Patrón
C52: {='Cálculos'!B49} -> 6 | D52: {=AVERAGE('Cálculos'!C49:G49)} -> 5.996 | E52: {=D52-C52} -> -0.004 | F52: {='Cálculos'!O49} -> 0.0064293597
C53: {='Cálculos'!B50} -> 15 | D53: {=AVERAGE('Cálculos'!C50:G50)} -> 15 | E53: {=D53-C53} -> 0 | F53: {='Cálculos'!O50} -> 0.0064293597
C54: {='Cálculos'!B51} -> 30 | D54: {=AVERAGE('Cálculos'!C51:G51)} -> 29.99 | E54: {=D54-C54} -> -0.01 | F54: {='Cálculos'!O51} -> 0.0064293597
C55: {='Cálculos'!B52} -> 45 | D55: {=AVERAGE('Cálculos'!C52:G52)} -> 44.98 | E55: {=D55-C55} -> -0.02 | F55: {='Cálculos'!O52} -> 0.0064293597
C56: {='Cálculos'!B53} -> 54 | D56: {=AVERAGE('Cálculos'!C53:G53)} -> 53.98 | E56: {=D56-C56} -> -0.02 | F56: {='Cálculos'!O53} -> 0.0064293597
H74: No. de certificado: (Calibration number) | J74: {=J$9} -> E-MK-0153/26
C75: CERTIFICADO DE CALIBRACIÓN (CALIBRATION CERTIFICATE) | H75: Fecha de calibración: (Calibration date) | J75: {=J$10} -> 46037
...

Sheet Anexo II

Sheet ETIQUETA
A1: CALIBRADO
A4: CERTIFICADO: | I4: {=Certificado!I3} -> E-MK-0153/26
A5: Fecha de calibración: | J5: {=Certificado!J5} -> 46037
A6: Vigencia de cliente: | J6: {=Certificado!J7} -> 46402
A7: ID: | D7: {=Certificado!D21} -> EVO-559
B8: Metkal | M8: MK-ET-01
