Workbook

Sheet Gráfico1

Sheet CALCULOS
C1: Cálculos e incertidumbres
A3: copiar del consecutivo | E3: Las áreas en amarillo indican las que deben ser editadas
E4: Las áreas en gris indican que NO deben ser editadas
A5: Informe | B5: cliente | C5: Dirección | D5: Ciudad | E5: Instrumento | F5: Alcance | G5: Marca | H5: Modelo | I5: Serie | J5: Identificación | K5: Recepción | L5: Fecha | M5: Vence | N5: Condición
A6: {='Certificado'!A1} -> M-MK-0497/26 | E6: {='Certificado'!B1} -> BALANZA DIGITAL DE 1 220 g | F6: 1200 g | G6: {='Certificado'!C1} -> AND | H6: {='Certificado'!D1} -> GF-1202A | I6: P3000164 | J6: EBASG018 | K6: 44308 | L6: 44308 | M6: 44673 | N6: 44308 | O6: Laura Gutierrez laura.gutierrez@csiclosures.com | P6: {=IF(M6<(NOW()+20),"vencido","vigente")} -> vencido | Q6: SAAV | R6: C
I8: Condiciones ambientales y carácterísticas de los equipos
G9: Vigencia
A10: Instrumentos patrón utilizados | G10: {=IF(((YEAR(M$6)-YEAR(L$6))*12)+(MONTH(M$6)-MONTH(L$6))<=0,"ERROR ",((YEAR(M$6)-YEAR(L$6))*12)+(MONTH(M$6)-MONTH(L$6)))} -> 12 | H10: Meses | I10: Magnitud | J10: Valor inicial | K10: Valor final | L10: División mínima del instrumento (d) | M10: Corrección del instrumento | N10: Incertidumbre del instrumento (k = 1) | O10: Unidades | Q10: Condiciones ambientales promedio
A11: Descripción del patrón utilizado. | C11: Alcance de medición | D11: ID | E11: No. de informe | F11: Vigencia | Q11: T. Ambiental promedio: | R11: {=AVERAGE(J13:K13)} -> 24.9 | S11: ⁰C
A12: Juego de pesas Patrón | C12: 20 kg a 1 000 kg | D12: MK-040 | E12: M-MK-0008/25 | F12: 46025 | Q12: H. relativa promedio: | R12: {=AVERAGE(J14:K14)} -> 48.5 | S12: %
A13: Juego de pesas Clase: E2 | C13: 1 mg a 5 kg | D13: MK-043 | E13: 5-26239 | F13: 46102 | I13: Temp. Ambiental | J13: 24.7 | K13: 25.1 | L13: 0.1 | M13: 0.1 | N13: 0.21 | O13: °C | Q13: P. barometrica promedio: | R13: {=AVERAGE(J15:K15)} -> 912 | S13: hPa
A14: Pesas Cilíndricas Clase: F1 | C14: 10 kg | D14: MK-044 | E14: 5-26240 | F14: 46102 | I14: H. relativa | J14: 49 | K14: 48 | L14: 1 | M14: 0.7 | N14: 1.8 | O14: % | Q14: Temperatura de las pesas: | R14: {=R11} -> 24.9 | S14: ⁰C
I15: Presión | J15: 912 | K15: 912 | L15: 1 | M15: -1.1 | N15: 0.082 | O15: hPa | Q15: Densidad de las pesas: | R15: 7 950 | S15: kg/m3
Q16: DTCONV | R16: {=ABS(R11-R14)} -> 0 | S16: ⁰C
G18: FALSE
G19: Datos de portada
G20: revisar
K21: Tiempo de estabilización
L22: Carga | M22: UNIDADES: | O22: t
K23: n | L23: {=F27} -> g | M23: s
K24: 1 | L24: 15 | M24: 5 | O24: s
A25: Clase: | B25: {=IF(E25<=1000,"Ordinaria",IF(E25<=10000,"Media",IF(E25<=100000,"Alta","Especial")))} -> Especial | D25: Div. Mínimas: | E25: {=E27/E30} -> 120000 | F25: e | K25: 2 | M25: 5 | O25: s
K26: 3 | M26: 5 | O26: s
E27: 1200 | F27: g | L27: Tiempo max | M27: {=MAX(M24:N26)*2} -> 10 | O27: s
D29: Resolución del instrumento d: | E29: 0.01 | F29: {=F27} -> g
D30: e: | E30: 0.01 | F30: {=F27} -> g
A34: Prueba de carga excéntrica ( 1/3 a 1/2 de MAX )
A35: Carga de prueba: | C35: 500 | D35: g | G35: Prueba de repetibilidad ( carga total entre el 50 %) | M35: Prueba de repetibilidad ( carga total entre el 100 %)
A37: Posición | B37: IL | C37: dIecc | D37: IdIeccI | G37: Carga de prueba: | I37: 500 | J37: {=F27} -> g | M37: Carga de prueba: | O37: 1000 | P37: {=F27} -> g
B38: {=F27} -> g | C38: {=B38} -> g | D38: {=B38} -> g | G38: Numero de prueba | J38: IL | M38: Numero de prueba | N38: I0 | P38: IL
A39: 1 | B39: 500.01
A40: 2 | B40: 500.02 | C40: {=B40-$B$39} -> 0.01 | D40: {=ABS(C40)} -> 0.01 | G40: 1 | H40: 0 | J40: 500 | M40: 1 | N40: 0 | P40: 1000.03
A41: 3 | B41: 500.01 | C41: {=B41-$B$39} -> 0 | D41: {=ABS(C41)} -> 0 | G41: 2 | H41: 0 | J41: 500.01 | M41: 2 | N41: 0 | P41: 1000.04
A42: 4 | B42: 500.02 | C42: {=B42-$B$39} -> 0.01 | D42: {=ABS(C42)} -> 0.01 | G42: 3 | H42: 0 | J42: 500.01 | M42: 3 | N42: 0 | P42: 1000.04
A43: 5 | B43: 500.02 | C43: {=B43-$B$39} -> 0.01 | D43: {=ABS(C43)} -> 0.01 | G43: 4 | H43: 0 | J43: 500.01 | M43: 4 | N43: 0 | P43: 1000.03
A44: Efecto de carga excentrica: | C44: {=MAX(D40:D43)} -> 0.01 | D44: {=B38} -> g | G44: 5 | H44: 0 | J44: 500.02 | M44: 5 | N44: 0 | P44: 1000.04
A45: u (ecc)= | B45: {=C44/(2*C35*SQRT(3))} -> 5.7735027e-06 | C45: Relativo | H45: s= | J45: {=STDEV(J40:K44)} -> 0.0070710678 | N45: s= | P45: 0
G46: Nota: | H46: Antes de realizar la prueba la indicacion se ajusta a cero | M46: Nota: | N46: Antes de realizar la prueba la indicacion se ajusta a cero
H47: la carga se aplicara por lo menos 5 veces y al menos 3 veces | N47: la carga se aplicara por lo menos 5 veces y al menos 3 veces
H48: cuando L ≥ 100 kg | N48: cuando L ≥ 100 kg
...

Sheet Certificado
A1: M-MK-0497/26 | B1: BALANZA DIGITAL DE 1 220 g | C1: AND | D1: GF-1202A | E1: T2118597 | F1: RBD-048 | G1: RECICLADORA INDUSTRIAL DE ACUMULADORES, S.A. DE C.V. | H1: CARRETERA A GARCIA KM.1.2 S/N CP. 66350 | I1: SANTA CATARINA | J1: NUEVO LEÓN | K1: 46070 | L1: 46070 | M1: {=K1+180} -> 46250 | N1: 46070
B3: CERTIFICADO DE CALIBRACIÓN (CALIBRATION CERTIFICATE) | G3: No. de certificado: (Certificate number) | I3: {=A1} -> M-MK-0497/26
C5: Datos del cliente: ( Customer ) | I5: Fecha de calibración: (Calibration date) | J5: {=K1} -> 46070
C6: Nombre: (Name) | D6: {=G1} -> RECICLADORA INDUSTRIAL DE ACUMULADORES, S.A. DE C.V. | I6: Fecha de emisión: (Date issued) | J6: {=L1} -> 46070
C7: Domicilio: (Address) | D7: {=H1} -> CARRETERA A GARCIA KM.1.2 S/N CP. 66350 | I7: Vigencia solicitada: (Due date required) | J7: {=M1} -> 46250
D8: {=CONCATENATE(I1,", ",J1)} -> SANTA CATARINA , NUEVO LEÓN | I8: Fecha de recepcion: (Reception date) | J8: {=N1} -> 46070
I9: Página (Page): | J9: 1 de 2
C11: Descripción del Instrumento: (Instrument description)
H12: Lugar de la calibración: | I12: INSTALACIONES DEL CLIENTE
C13: Instrumento : | D13: {=B1} -> BALANZA DIGITAL DE 1 220 g
C14: (Instrument) | G14: Temperatura : | I14: 23.8
C15: Marca: | D15: {=C1} -> AND | G15: (Temperature)
C16: (Manufacturer) | G16: Humedad Relativa : | I16: 0.418
C17: Modelo: | D17: {=D1} -> GF-1202A | G17: (Relative Humidity)
C18: (Model)
C19: No. serie: | D19: {=E1} -> T2118597
C20: (Serial number)
C21: ID Interno: | D21: {=F1} -> RBD-048
C22: (Customer ID)
C23: Intervalo : | D23: {='CALCULOS'!E27} -> 1200 | E23: {='CALCULOS'!F27} -> g
C24: (Range)
C25: Resolución: | D25: {='CALCULOS'!E29} -> 0.01 | E25: {='CALCULOS'!F27} -> g
C26: (Resolution)
C29: El laboratorio de calibraciones cuenta con un sistema de Gestión de Procesos basado en: | I29: ISO/IEC 17025:2017
C30: Requisitos generales para la competencia de los laboratorios de ensayo y de calibración.
C32: Procedimiento utilizado | E32: 7.2M1 | G32: Método: | H32: Comparación directa
C33: (Procedure used) | G33: (Method)
C35: Trazabilidad Metrologica (Metrological Traceability)
C37: Descripción del patrón
E38: Certificado / Informe | G38: Vigencia | I38: ID interno | J38: Intervalo
C39: (Description) | E39: (Certificate number) | G39: (Validity) | I39: (Internal ID) | J39: (Range)
B40: {='CALCULOS'!A13} -> Juego de pesas Clase: E2 | E40: {='CALCULOS'!E13} -> 5-26239 | G40: {='CALCULOS'!F13} -> 46102 | I40: {='CALCULOS'!D13} -> MK-043 | J40: {='CALCULOS'!C13} -> 1 mg a 5 kg
B41: {='CALCULOS'!A13} -> Juego de pesas Clase: E2 | E41: {='CALCULOS'!E13} -> 5-26239 | G41: {='CALCULOS'!F13} -> 46102 | I41: {='CALCULOS'!D13} -> MK-043 | J41: {='CALCULOS'!C13} -> 1 mg a 5 kg
B42: {='CALCULOS'!A13} -> Juego de pesas Clase: E2 | E42: {='CALCULOS'!E13} -> 5-26239 | G42: {='CALCULOS'!F13} -> 46102 | I42: {='CALCULOS'!D13} -> MK-043 | J42: {='CALCULOS'!C13} -> 1 mg a 5 kg
C45: Nota: La incertidumbre de los patrones es acorde a 1/3 del EMT, siendo clasificadas OIML
D47: Calibró: | E47: Daniel A. Solorio Gallegos | G47: Firma
D48: (Calibrated by:) | E48: Ingeniero de Servicio | G48: (Signature)
D50: Aprobó: | E50: Sergio Garza Rangel | G50: Firma
D51: (Approved by:) | E51: Director Administrativo | G51: (Signature)

Sheet Resultados I
H9: No. de certificado: (Calibration number) | J9: {='Certificado'!I3} -> M-MK-0497/26
C10: CERTIFICADO DE CALIBRACIÓN (CALIBRATION CERTIFICATE) | H10: Fecha de calibración: (Calibration date) | J10: {='Certificado'!J5} -> 46070
H11: Fecha de emision: (Issued date) | J11: {='Certificado'!J6} -> 46070
H12: Página: (Page) | J12: 2 de 2
C14: Prueba de carga excentrica | H14: Prueba de Repetibilidad
C15: Valor nominal | D15: Indicación | F15: Posición del receptor de carga | H15: Carga | I15: Desviación estandar
B16: Zona | C16: g | D16: g | H16: g | I16: g
B17: 1 | C17: {='CALCULOS'!C35} -> 500 | D17: {='CALCULOS'!B39} -> 500.01 | H17: {='CALCULOS'!J44} -> 500.02 | I17: {='CALCULOS'!J45} -> 0.0070710678 | J17: 0.5
B18: 2 | D18: {='CALCULOS'!B40} -> 500.02
B19: 3 | D19: {='CALCULOS'!B41} -> 500.01
B20: 4 | D20: {='CALCULOS'!B42} -> 500.02 | F20: Frente
B21: 5 | D21: {='CALCULOS'!B43} -> 500.02
C22: Efecto de carga excentrica | E22: {='CALCULOS'!C44} -> 0.01
C24: Error de Indicacion
C25: Carga Nominal | D25: Error de Indicación | F25: Incertidumbre expandida k=2 | G25: Gráfica de error de indicación
C27: g | D27: {=C27} -> g | F27: {=D27} -> g
C28: {='CALCULOS'!B59} -> 5 | D28: {='CALCULOS'!Q59} -> -6e-06 | F28: {='CALCULOS'!S59} -> 0.010328132 | M28: {=D23} -> 0 | N28: {=-E28} | O28: {=-F28} -> -0.010328132
C29: {='CALCULOS'!B60} -> 10 | D29: {='CALCULOS'!Q60} -> 3.9e-05 | F29: {='CALCULOS'!S60} -> 0.010329026 | M29: {=D24} | N29: {=-E29} | O29: {=-F29} -> -0.010329026 | T29: 0.01
C30: {='CALCULOS'!B61} -> 15 | D30: {='CALCULOS'!Q61} -> -6.1e-05 | F30: {='CALCULOS'!S61} -> 0.010332916 | N30: {=-E30} | O30: {=-F30} -> -0.010332916
C31: {='CALCULOS'!B62} -> 100 | D31: {='CALCULOS'!Q62} -> -0.01008 | F31: {='CALCULOS'!S62} -> 0.010398626 | M31: {=D28} -> -6e-06 | N31: {=-E31} | O31: {=-F31} -> -0.010398626 | P31: {=D28+F28} -> 0.010322132 | Q31: {=D28-F28} -> -0.010334132 | R31: {=-I31} -> 0
C32: {='CALCULOS'!B63} -> 150 | D32: {='CALCULOS'!Q63} -> -0.00996 | F32: {='CALCULOS'!S63} -> 0.01048263 | M32: {=D29} -> 3.9e-05 | N32: {=-E32} | O32: {=-F32} -> -0.01048263 | P32: {=D29+F29} -> 0.010368026 | Q32: {=D29-F29} -> -0.010290026 | R32: {=-I32} -> 0 | T32: 1
A33: {='CALCULOS'!B64} -> 500 | C33: {='CALCULOS'!B64} -> 500 | D33: {='CALCULOS'!Q64} -> 0.010079 | F33: {='CALCULOS'!S64} -> 0.011845551 | M33: {=D30} -> -6.1e-05 | N33: {=-E33} | O33: {=-F33} -> -0.011845551 | P33: {=D30+F30} -> 0.010271916 | Q33: {=D30-F30} -> -0.010393916 | R33: {=-I33} -> 0 | T33: 10
A34: {='CALCULOS'!B65} -> 800 | C34: {='CALCULOS'!B65} -> 800 | D34: {='CALCULOS'!Q65} -> 0.030118 | F34: {='CALCULOS'!S65} -> 0.013871587 | M34: {=D31} -> -0.01008 | N34: {=-E34} | O34: {=-F34} -> -0.013871587 | P34: {=D31+F31} -> 0.00031862616 | Q34: {=D31-F31} -> -0.020478626 | R34: {=-I34} -> 0 | T34: 20
A35: {='CALCULOS'!B66} -> 900 | C35: {='CALCULOS'!B66} -> 900 | D35: {='CALCULOS'!Q66} -> 0.01996 | F35: {='CALCULOS'!S66} -> 0.014674568 | M35: {=D32} -> -0.00996 | N35: {=-E35} | O35: {=-F35} -> -0.014674568 | P35: {=D32+F32} -> 0.00052262972 | Q35: {=D32-F32} -> -0.02044263 | R35: {=-I35} -> 0 | T35: 40
A36: {='CALCULOS'!B67} -> 1000 | C36: {='CALCULOS'!B67} -> 1000 | D36: {='CALCULOS'!Q67} -> 0.029059 | F36: {='CALCULOS'!S67} -> 0.015526404 | M36: {=D33} -> 0.010079 | N36: {=-E36} | O36: {=-F36} -> -0.015526404 | P36: {=D33+F33} -> 0.021924551 | Q36: {=D33-F33} -> -0.0017665505 | R36: {=-I36} -> 0 | T36: 60
A37: {='CALCULOS'!B68} -> 1200 | C37: {='CALCULOS'!B68} -> 1200 | D37: {='CALCULOS'!Q68} -> 0.03892 | F37: {='CALCULOS'!S68} -> 0.01731809 | M37: {=D34} -> 0.030118 | N37: {=-E37} | O37: {=-F37} -> -0.01731809 | P37: {=D34+F34} -> 0.043989587 | Q37: {=D34-F34} -> 0.016246413 | R37: {=-I37} -> 0
A38: {='CALCULOS'!B69} -> 0 | B38: {='CALCULOS'!Q69} -> 0 | D38: {='CALCULOS'!F69} -> 0.005 | E38: {='CALCULOS'!S69} -> 0.010327956 | F38: {=IF((ABS(B38)<ABS(D38)),IF((ABS(E38)+ABS(B38))>ABS(D38)," No cumple","Cumple"),"No cumple")} -> No cumple | H38: Incertidumbre expandida | M38: {=D35} -> 0.01996 | P38: {=D35+F35} -> 0.034634568 | Q38: {=D35-F35} -> 0.0052854319 | R38: {=-I38} -> 0
H39: Error de indicación | M39: {=D36} -> 0.029059 | O39: 0.1 | P39: {=D36+F36} -> 0.044585404 | Q39: {=D36-F36} -> 0.013532596 | R39: {=-I39} -> 0
M40: {=D37} -> 0.03892 | P40: {=D37+F37} -> 0.05623809 | Q40: {=D37-F37} -> 0.02160191 | R40: {=-I40} -> 0
B47: Carga Excentrica | D47: Prueba de repetibilidad | G47: Prueba de exactitud | M47: {=C28} -> 5
A50: Nota: El equipo cumple de acuerdo con las especificaciones del fabricante. | M50: {=C29} -> 10
M52: {=C30} -> 15
M53: {=C31} -> 100
M54: {=C32} -> 150
M55: {=C33} -> 500
M56: {=C34} -> 800
M57: {=C35} -> 900
M58: {=C36} -> 1000
M59: {=C37} -> 1200

Sheet Anexo II

Sheet ETIQUETA
A1: CALIBRADO
A4: CERTIFICADO: | I4: {='Certificado'!I3} -> M-MK-0497/26
A5: Fecha de calibración: | J5: {='Certificado'!J5} -> 46070
A6: Vigencia de cliente: | J6: {='Certificado'!J7} -> 46250
A7: ID: | D7: {='Certificado'!D21} -> RBD-048
B8: Metkal | M8: MK-ET-01

Sheet Clase
D2: CLASIFICACIÓN DE LOS INSTRUMENTOS PARA PESAR
O4: ERRORES MAXIMOS TOLERADOS DE LOS INSTRUMENTOS PARA PESAR EN PRUEBAS INICIALES
A5: n
F6: Especial | O6: Errores máximos | P6: Para cargas m expresadas en escalones de verificación (e)
A7: > 100 000 | F7: I | O7: permitidos | P7: I | Q7: I I | R7: I I I | S7: I I I I
O8: ± 0,5 e | P8: 0 < m < 50 000 | Q8: 0 < m < 5 000 | R8: 0 < m < 500 | S8: 0 < m < 50
A9: 100 000 | O9: ± 1 e | P9: 50 000 < m < 200 000 | Q9: 5 000 < m < 20 000 | R9: 500 < m < 2 000 | S9: 500 < m < 200
C10: Fina y Especial | G10: Fina y Especial | O10: ± 1,5 e | P10: 200 000 < m | Q10: 20 000 < m < 100 000 | R10: 2 000 < m < 10 000 | S10: 200 < m < 1 000
C11: I I I | G11: I I I
L12: espacios a llenar | S12: n=max/e
P13: Clase | Q13: Intervalos | R13: Tolerancia
A14: 50 000 | P14: i | S14: Div min (d)
G15: Fina I I | K15: I | L15: II | M15: III | N15: IIII | O15: alcance | Q15: {=IF(P$14=K$15,K16*$P$16,IF(P$14=L$15,L16*$P$16,IF(P$14=M$15,M16*$P$16,N16*$P$16)))} -> 0 | R15: {=(0.5*P16)*2} -> 0 | S15: e=d | T15: {=T14*1} -> 0
G16: ( 50 e ) | K16: 50000 | L16: 5000 | M16: 500 | N16: 50 | O16: e | P16: {=T17} -> 0 | Q16: {=IF(P$14=K$15,K17*$P$16,IF(P$14=L$15,L17*$P$16,IF(P$14=M$15,M17*$P$16,N17*$P$16)))} -> 0 | R16: {=(1*P16)*2} -> 0 | S16: e=5d | T16: {=T14*5} -> 0
C17: Fina I I | K17: 200000 | L17: 20000 | M17: 2000 | N17: 200 | O17: n | P17: {=P15/P16} | Q17: {=IF(P$14=K$15,K18*$P$16,IF(P$14=L$15,L18*$P$16,IF(P$14=M$15,M18*$P$16,N18*$P$16)))} -> 0 | R17: {=(1.5*P16)*2} -> 0 | S17: e=10d | T17: {=T14*10} -> 0
A18: 10 000 | C18: ( 20 e ) | E18: Media y Fina | H18: Media y Fina | L18: 100000 | M18: 10000 | N18: 1000
E19: I I I I I | H19: I I I I I
A21: 5 000 | O21: Clase de exactitud | P21: División de verificación | Q21: Número de escalones de verificación n=max/e | S21: Alcance Mínimo (Min)
E22: Media I I I | H22: Media I I I | Q22: Mínimo | R22: Máximo | S22: Límite inferior
E23: ( 20 e ) | H23: ( 20 e ) | O23: Especial I | P23: 0,001 g < e* | Q23: 50 000 | R23: --- | S23: 100 e | T23: 100
A24: 1 000 | O24: Fina I I | P24: 0,001 g < e < 0,05 g | Q24: 100 | R24: 100 000 | S24: 20 e | T24: 20
H25: Ordinaria I I I I | P25: 0,1 g < e | Q25: 5 000 | R25: 100 000 | S25: 50 e | T25: 50
H26: Media I I I | O26: Media I I I | P26: 0,1 g < e < 2 g | Q26: 100 | R26: 10 000 | S26: 20 e | T26: 20
A27: 500 | P27: 5 g < e | Q27: 500 | R27: 10 000 | S27: 20 e | T27: 20
G28: Ordinaria I I I | H28: ( 20 e ) | O28: Ordinaria I I I I | P28: 5 g < e | Q28: 100 | R28: 1 000 | S28: 10 e | T28: 10
A29: 100
B31: 1 mg | C31: 5 mg 50 mg | D31: 100 mg | E31: 1 g | F31: 2 g | G31: 5 g | H31: , , , , , , , , , | I31: > 5 g | J31: e

Sheet Pesas
J3: 44136 | Q3: 44022 | AF3: 44415
J4: MK-020 | K4: VALOR NOMINAL | L4: VALOR DE MASA CONVENCIONAL | O4: Incertidumbre Expandida | Q4: MK-021 | R4: VALOR NOMINAL | S4: {=U4} -> VALOR DE MASA CONVENCIONAL | T4: Incertidumbre Expandida | U4: VALOR DE MASA CONVENCIONAL | X4: Incertidumbre Expandida | AF4: CTK-069 | AG4: VALOR NOMINAL | AH4: VALOR DE MASA CONVENCIONAL | AK4: Incertidumbre Expandida
K5: g | M5: g | O5: g | Q5: # | R5: g | V5: g | X5: g | AG5: g | AI5: g | AK5: g
J6: 1 g | K6: 1 | L6: 1 | M6: + | N6: 1.1e-05 | O6: 1e-05 | Q6: 1 | R6: 20000 | S6: {=U6+W6} -> 20000.36 | T6: {=X6} -> 0.33 | U6: 20000 | V6: + | W6: 0.36 | X6: 0.33 | AF6: 100 mg | AG6: 0.1 | AH6: 0.1 | AI6: + | AJ6: 8e-06 | AK6: 1.7e-05
J7: 2(*) g | K7: 2 | L7: 2 | M7: + | N7: 2e-06 | O7: 1.3e-05 | Q7: 2 | R7: 20000 | S7: {=U7+W7} -> 20000.38 | T7: {=X7} -> 0.33 | U7: 20000 | V7: + | W7: 0.38 | X7: 0.33 | AA7: valor conv | AB7: incer exp. | AF7: 200 mg | AG7: 0.2 | AH7: 0.2 | AI7: + | AJ7: 2.1e-05 | AK7: 2e-05
J8: 2(**) g | K8: 2 | L8: 2 | M8: + | N8: 5e-06 | O8: 1.3e-05 | Q8: 3 | R8: 20000 | S8: {=U8+W8} -> 20000.39 | T8: {=X8} -> 0.33 | U8: 20000 | V8: + | W8: 0.39 | X8: 0.33 | Z8: 1 | AA8: {=L6+N6} -> 1.000011 | AB8: {=O6} -> 1e-05 | AF8: 200(*) mg | AG8: 0.2 | AH8: 0.2 | AI8: + | AJ8: 9e-06 | AK8: 2e-05
J9: 5 g | K9: 5 | L9: 5 | M9: + | N9: 1.6e-05 | O9: 1.7e-05 | Q9: 4 | R9: 20000 | S9: {=U9+W9} -> 20000.39 | T9: {=X9} -> 0.33 | U9: 20000 | V9: + | W9: 0.39 | X9: 0.33 | Z9: 2 | AA9: {=L7+N7} -> 2.000002 | AB9: {=O7} -> 1.3e-05 | AF9: 500 mg | AG9: 0.5 | AH9: 0.5 | AI9: + | AJ9: 3e-06 | AK9: 2.7e-05
J10: 10 g | K10: 10 | L10: 10 | M10: + | N10: 6e-06 | O10: 2e-05 | Q10: 5 | R10: 20000 | S10: {=U10+W10} -> 20000.31 | T10: {=X10} -> 0.33 | U10: 20000 | V10: + | W10: 0.31 | X10: 0.33 | Z10: 2 | AA10: {=L8+N8} -> 2.000005 | AB10: {=O8} -> 1.3e-05 | AF10: 1 g | AG10: 1 | AH10: 1 | AI10: + | AJ10: 0.000119 | AK10: 3.3e-05
J11: 20(*) g | K11: 20 | L11: 20 | M11: + | N11: 1e-06 | O11: 2.7e-05 | Q11: 6 | R11: 20000 | S11: {=U11+W11} -> 20000.36 | T11: {=X11} -> 0.33 | U11: 20000 | V11: + | W11: 0.36 | X11: 0.33 | Z11: 5 | AA11: {=L9+N9} -> 5.000016 | AB11: {=O9} -> 1.7e-05 | AF11: 2(*) g | AG11: 2 | AH11: 2 | AI11: + | AJ11: 2.4e-05 | AK11: 4e-05
J12: 20(**) g | K12: 20 | L12: 20 | M12: + | N12: 0.000149 | O12: 2.7e-05 | Q12: 7 | R12: 20000 | S12: {=U12+W12} -> 20000.37 | T12: {=X12} -> 0.33 | U12: 20000 | V12: + | W12: 0.37 | X12: 0.33 | Z12: 10 | AA12: {=L10+N10} -> 10.000006 | AB12: {=O10} -> 2e-05 | AF12: 2(**) g | AG12: 2 | AH12: 2 | AI12: + | AJ12: 2.5e-05 | AK12: 4e-05
J13: 50 g | K13: 50 | L13: 50 | M13: + | N13: 2.3e-05 | O13: 3.3e-05 | Q13: 8 | R13: 20000 | S13: {=U13+W13} -> 20000.37 | T13: {=X13} -> 0.33 | U13: 20000 | V13: + | W13: 0.37 | X13: 0.33 | Z13: 20 | AA13: {=L11+N11} -> 20.000001 | AB13: {=O11} -> 2.7e-05 | AF13: 5 g | AG13: 5 | AH13: 5 | AI13: + | AJ13: 2e-05 | AK13: 5.3e-05
J14: 100 g | K14: 100 | L14: 100 | M14: + | N14: 0.000121 | O14: 5.3e-05 | Q14: 9 | R14: 20000 | S14: {=U14+W14} -> 20000.28 | T14: {=X14} -> 0.33 | U14: 20000 | V14: + | W14: 0.28 | X14: 0.33 | Z14: 20 | AA14: {=L12+N12} -> 20.000149 | AB14: {=O12} -> 2.7e-05 | AF14: 10 g | AG14: 10 | AH14: 10 | AI14: + | AJ14: 9.7e-05 | AK14: 6.7e-05
J15: 200 g | K15: 200 | L15: 200 | M15: + | N15: 0.0005 | O15: 0.0001 | Q15: 10 | R15: 20000 | S15: {=U15+W15} -> 20000.36 | T15: {=X15} -> 0.33 | U15: 20000 | V15: + | W15: 0.36 | X15: 0.33 | Z15: 50 | AA15: {=L13+N13} -> 50.000023 | AB15: {=O13} -> 3.3e-05 | AF15: 20(*) g | AG15: 20 | AH15: 20 | AI15: + | AJ15: 1.4e-05 | AK15: 8.3e-05
J16: 200 g | K16: 200 | L16: 200 | M16: + | N16: 0.00038 | O16: 0.0001 | Q16: 11 | R16: 20000 | S16: {=U16+W16} -> 20000.37 | T16: {=X16} -> 0.33 | U16: 20000 | V16: + | W16: 0.37 | X16: 0.33 | Z16: {=Z15+Z12+Z13} -> 80 | AA16: {=AA15+AA13+AA12} -> 80.00003 | AB16: {=SQRT(AB15^2+AB13^2+AB12^2)} -> 4.7095647e-05 | AF16: 20(**) g | AG16: 20 | AH16: 20 | AI16: + | AJ16: 2.8e-05 | AK16: 8.3e-05
J17: 500 g | K17: 500 | L17: 500 | M17: + | N17: 0.00016 | O17: 0.00027 | Q17: 12 | R17: 20000 | S17: {=U17+W17} -> 20000.31 | T17: {=X17} -> 0.33 | U17: 20000 | V17: + | W17: 0.31 | X17: 0.33 | Z17: 100 | AA17: {=L14+N14} -> 100.00012 | AB17: {=O14} -> 5.3e-05 | AF17: 50 g | AG17: 50 | AH17: 50 | AI17: + | AJ17: 0.00064 | AK17: 0.0001
J18: 1 kg | K18: 1000 | L18: 1000 | M18: + | N18: 0.0001 | O18: 0.00053 | Q18: 13 | R18: 20000 | S18: {=U18+W18} -> 20000.38 | T18: {=X18} -> 0.33 | U18: 20000 | V18: + | W18: 0.38 | X18: 0.33 | Z18: {=Z17+Z15} -> 150 | AA18: {=AA17+AA15} -> 150.00014 | AB18: {=SQRT(AB17^2+AB15^2)} -> 6.2433965e-05 | AF18: 100 g | AG18: 100 | AH18: 100 | AI18: + | AJ18: 0.00107 | AK18: 0.00017
J19: 2 (*)kg | K19: 2000 | L19: 2000 | M19: + | N19: 0.0026 | O19: 0.001 | Q19: 14 | R19: 20000 | S19: {=U19+W19} -> 20000.35 | T19: {=X19} -> 0.33 | U19: 20000 | V19: + | W19: 0.35 | X19: 0.33 | Z19: 200 | AA19: {=L15+N15} -> 200.0005 | AB19: {=O15} -> 0.0001 | AF19: 200 g | AG19: 200 | AH19: 200 | AI19: + | AJ19: 0.00129 | AK19: 0.00033
J20: 2 (**)kg | K20: 2000 | L20: 2000 | M20: + | N20: 0.0015 | O20: 0.001 | Q20: 15 | R20: 20000 | S20: {=U20+W20} -> 20000.35 | T20: {=X20} -> 0.33 | U20: 20000 | V20: + | W20: 0.35 | X20: 0.33 | Z20: 200 | AA20: {=L16+N16} -> 200.00038 | AB20: {=O16} -> 0.0001 | AF20: 200 g | AG20: 200 | AH20: 200 | AI20: + | AJ20: 0.00136 | AK20: 0.00033
J21: 5 kg | K21: 5000 | L21: 5000 | M21: + | N21: 0.0024 | O21: 0.0027 | Q21: 16 | R21: 20000 | S21: {=U21+W21} -> 20000.36 | T21: {=X21} -> 0.33 | U21: 20000 | V21: + | W21: 0.36 | X21: 0.33 | Z21: {=Z19+Z15} -> 250 | AA21: {=AA19+AA15} -> 250.00052 | AB21: {=SQRT(AB20^2+AB15^2)} -> 0.00010530432 | AF21: 500 g | AG21: 500 | AH21: 500 | AI21: + | AJ21: 0.00049 | AK21: 0.00083
Q22: 17 | R22: 20000 | S22: {=U22+W22} -> 20000.39 | T22: {=X22} -> 0.33 | U22: 20000 | V22: + | W22: 0.39 | X22: 0.33 | Z22: {=Z21+Z17} -> 350 | AA22: {=AA21+AA17} -> 350.00064 | AB22: {=SQRT(AB21^2+AB17^2)} -> 0.00011788978 | AF22: 1 (*)kg | AG22: 1000 | AH22: 1000 | AI22: + | AJ22: 0.0006 | AK22: 0.0017
Q23: 18 | R23: 20000 | S23: {=U23+W23} -> 20000.35 | T23: {=X23} -> 0.33 | U23: 20000 | V23: + | W23: 0.35 | X23: 0.33 | Z23: 500 | AA23: {=L17+N17} -> 500.00016 | AB23: {=O17} -> 0.00027 | AF23: 1 (*1*)kg | AG23: 1000 | AH23: 1000 | AI23: + | AJ23: 0.0065 | AK23: 0.0017
Q24: 19 | R24: 20000 | S24: {=U24+W24} -> 20000.34 | T24: {=X24} -> 0.33 | U24: 20000 | V24: + | W24: 0.34 | X24: 0.33 | Z24: {=Z23+Z19+Z17} -> 800 | AA24: {=AA23+AA19+AA17} -> 800.00078 | AB24: {=SQRT(AB23^2+AB19^2+AB17^2)} -> 0.00029276099 | AF24: 1 (*2*)kg | AG24: 1000 | AH24: 1000 | AI24: + | AJ24: 0.0057 | AK24: 0.0017
Q25: 20 | R25: 20000 | S25: {=U25+W25} -> 20000.33 | T25: {=X25} -> 0.33 | U25: 20000 | V25: + | W25: 0.33 | X25: 0.33 | Z25: 1000 | AA25: {=L18+N18} -> 1000.0001 | AB25: {=O18} -> 0.00053 | AF25: 1 (*4*)kg | AG25: 1000 | AH25: 1000 | AI25: + | AJ25: 0.0048 | AK25: 0.0017
Q26: 21 | R26: 20000 | S26: {=U26+W26} -> 20000.41 | T26: {=X26} -> 0.33 | U26: 20000 | V26: + | W26: 0.41 | X26: 0.33 | Z26: {=Z25+Z23} -> 1500 | AA26: {=AA25+AA23} -> 1500.0003 | AB26: {=SQRT(AB25^2+AB23^2)} -> 0.00059481089 | AF26: 2 kg | AG26: 2000 | AH26: 2000 | AI26: + | AJ26: 0.0222 | AK26: 0.0033
Q27: 22 | R27: 20000 | S27: {=U27+W27} -> 20000.27 | T27: {=X27} -> 0.33 | U27: 20000 | V27: + | W27: 0.27 | X27: 0.33 | Z27: 2000 | AA27: {=L19+N19} -> 2000.0026 | AB27: {=O19} -> 0.001
J28: 44395 | Q28: 23 | R28: 20000 | S28: {=U28+W28} -> 20000.38 | T28: {=X28} -> 0.33 | U28: 20000 | V28: + | W28: 0.38 | X28: 0.33 | Z28: 2000 | AA28: {=L20+N20} -> 2000.0015 | AB28: {=O20} -> 0.001
J29: CTK-173 | K29: VALOR NOMINAL | L29: VALOR DE MASA CONVENCIONAL | O29: Incertidumbre Expandida | Q29: 24 | R29: 20000 | S29: {=U29+W29} -> 20000.41 | T29: {=X29} -> 0.33 | U29: 20000 | V29: + | W29: 0.41 | X29: 0.33 | Z29: {=Z27+Z23} -> 2500 | AA29: {=AA27+AA23} -> 2500.0028 | AB29: {=SQRT(AB27^2+AB23^2)} -> 0.0010358089
K30: g | M30: g | O30: g | Q30: 25 | R30: 20000 | S30: {=U30+W30} -> 20000.37 | T30: {=X30} -> 0.33 | U30: 20000 | V30: + | W30: 0.37 | X30: 0.33 | Z30: {=Z29+Z25} -> 3500 | AA30: {=AA29+AA25} -> 3500.0029 | AB30: {=SQRT(AB29^2+AB25^2)} -> 0.0011635291
J31: 10 kg | K31: 10000 | L31: 10000 | M31: + | N31: 3.4e-05 | O31: 1.7e-05 | Q31: 26 | R31: 20000 | S31: {=U31+W31} -> 20000.38 | T31: {=X31} -> 0.33 | U31: 20000 | V31: + | W31: 0.38 | X31: 0.33 | Z31: 5000 | AA31: {=L21+N21} -> 5000.0024 | AB31: {=O21} -> 0.0027
J32: 20 kg | K32: 20000 | L32: 20000 | M32: + | N32: 3.7e-05 | O32: 3.3e-05 | Q32: 27 | R32: 20000 | S32: {=U32+W32} -> 20000.38 | T32: {=X32} -> 0.33 | U32: 20000 | V32: + | W32: 0.38 | X32: 0.33 | Z32: {=Z31+Z27+Z25} -> 8000 | AA32: {=AA31+AA27+AA25} -> 8000.0051 | AB32: {=SQRT(AB31^2+AB27^2+AB25^2)} -> 0.0029276099
Q33: 28 | R33: 20000 | S33: {=U33+W33} -> 20000.31 | T33: {=X33} -> 0.33 | U33: 20000 | V33: + | W33: 0.31 | X33: 0.33 | Z33: 10000 | AA33: {=AA32+AA28} -> 10000.007 | AB33: {=SQRT(AB32^2+AB28^2)} -> 0.0030936871
Q34: 29 | R34: 20000 | S34: {=U34+W34} -> 20000.29 | T34: {=X34} -> 0.33 | U34: 20000 | V34: + | W34: 0.29 | X34: 0.33 | Z34: {=Z33+Z31} -> 15000 | AA34: {=AA33+AA31} -> 15000.009 | AB34: {=SQRT(AB33^2+AB31^2)} -> 0.0041062026
Q35: 30 | R35: 20000 | S35: {=U35+W35} -> 20000.32 | T35: {=X35} -> 0.33 | U35: 20000 | V35: + | W35: 0.32 | X35: 0.33 | Z35: 20000 | AA35: {=L32+N32} -> 20000 | AB35: {=O32} -> 3.3e-05
Q36: 31 | R36: 20000 | S36: {=U36+W36} -> 20000.32 | T36: {=X36} -> 0.33 | U36: 20000 | V36: + | W36: 0.32 | X36: 0.33 | Z36: {=Z35+Z33} -> 30000 | AA36: {=AA35+AA33} -> 30000.007 | AB36: {=SQRT(AB35^2+AB33^2)} -> 0.0030938631
Q37: 32 | R37: 20000 | S37: {=U37+W37} -> 20000.35 | T37: {=X37} -> 0.33 | U37: 20000 | V37: + | W37: 0.35 | X37: 0.33
Q38: 33 | R38: 20000 | S38: {=U38+W38} -> 20000.37 | T38: {=X38} -> 0.33 | U38: 20000 | V38: + | W38: 0.37 | X38: 0.33
Q39: 34 | R39: 20000 | S39: {=U39+W39} -> 20000.38 | T39: {=X39} -> 0.33 | U39: 20000 | V39: + | W39: 0.38 | X39: 0.33
Q40: 35 | R40: 20000 | S40: {=U40+W40} -> 20000.38 | T40: {=X40} -> 0.33 | U40: 20000 | V40: + | W40: 0.38 | X40: 0.33
Q41: 36 | R41: 20000 | S41: {=U41+W41} -> 20000.27 | T41: {=X41} -> 0.33 | U41: 20000 | V41: + | W41: 0.27 | X41: 0.33
Q42: 37 | R42: 20000 | S42: {=U42+W42} -> 20000.34 | T42: {=X42} -> 0.33 | U42: 20000 | V42: + | W42: 0.34 | X42: 0.33
...
